<?xml version="0.0" ?>
<robot name="Servo">
  <link name="Plate">
    <contact>
	  <!--<stiffness value="10000.0"/>-->
	  <!--<damping value="10.0"/>-->
	  <lateral_friction value="0.9"/>
    </contact>
    <inertial>
      <origin rpy="0 0 0" xyz="0 0 0"/>
       <mass value="0.0825"/>
       <inertia  ixx="1.0" ixy="0.0"  ixz="0.0"  iyy="1.0"  iyz="0.0"  izz="1.0" />
    </inertial>
    <visual>
      <origin rpy="0 0 0" xyz="0.13 0.75 -0.2"/>
      <geometry>
	<mesh filename="ServoPlate.stl" scale="1 1 1" />
      </geometry>
      <material name="viridis_yellow">
	<color rgba="0.99 0.90 0.15 1.0" />
      </material>
    </visual>
    <collision>
      <origin rpy="0 0 0" xyz="0.0 0 0"/>
      <geometry>
        <box size="0.061 0.055 0.055" />
      </geometry>
    </collision>
  </link>
  <link name="Body">
    <contact>
	  <!--<stiffness value="10000.0"/>-->
	  <!--<damping value="10.0"/>-->
	  <lateral_friction value="0.9"/>
    </contact>
    <inertial>
      <origin rpy="0 0 0" xyz="0 0 0"/>
       <mass value="0.0825"/>
       <inertia  ixx="1.0" ixy="0.0"  ixz="0.0"  iyy="1.0"  iyz="0.0"  izz="1.0" />
    </inertial>
    <visual>
      <origin rpy="0 0 0" xyz="0.115 0.75 -0.2"/>
      <geometry>
	<mesh filename="Servo.stl" scale="1 1 1" />
      </geometry>
      <material name="viridis_green">
	<color rgba="0.13 0.57 0.55 1.0" />
      </material>
    </visual>
    <collision>
      <origin rpy="0 0 0" xyz="0 0 0.0"/>
      <geometry>
        <box size="0.055 0.061 0.061" />
      </geometry>
    </collision>
  </link>
  <joint name="Joint" type="revolute">
	<origin xyz="-0.02 0.0 0.0" />
	<parent link="Body" />
	<child link="Plate" />
	<axis xyz="0 0 1" />
	<limit effort="1.8" lower="-1.57" upper="1.57" velocity="10.6" />
  </joint>
</robot>

