<?xml version="0.0" ?>
<robot name="Servo">
  <link name="Body">
  <contact>
	  <friction_anchor/>
	  <stiffness value="3000.0"/>
	  <damping value="100.0"/>
	  <spinning_friction value=".3"/>
	  <lateral_friction value="1"/>
  </contact>
    <inertial>
      <origin rpy="0 0 0" xyz="0 0 0"/>
       <mass value="0.0825"/>
			 <inertia ixx="0" ixy="0" ixz="0" iyy="0" iyz="0" izz="0"/>
    </inertial>
    <visual>
      <origin rpy="0 0 0" xyz="0.115 0.75 -0.2"/>
      <geometry>
				<mesh filename="Servo.stl" scale="1 1 1" />
      </geometry>
    </visual>
    <collision>
      <origin rpy="0 0 0" xyz="0 0 0.0"/>
      <geometry>
        <box size="0.055 0.061 0.061" />
      </geometry>
    </collision>
  </link>
  <link name="Plate">
  <contact>
	  <friction_anchor/>
	  <stiffness value="3000.0"/>
	  <damping value="100.0"/>
	  <spinning_friction value=".3"/>
	  <lateral_friction value="1"/>
  </contact>
    <inertial>
      <origin rpy="0 0 0" xyz="0 0 0"/>
       <mass value="0.0825"/>
			 <inertia ixx="0" ixy="0" ixz="0" iyy="0" iyz="0" izz="0"/>
    </inertial>
    <visual>
      <origin rpy="0 0 0" xyz="0.13 0.75 -0.2"/>
      <geometry>
				<mesh filename="ServoPlate.stl" scale="1 1 1" />
      </geometry>
    </visual>
    <collision>
      <origin rpy="0 0 0" xyz="0.0 0 0"/>
      <geometry>
        <box size="0.061 0.055 0.055" />
      </geometry>
    </collision>
  </link>
  <joint name="Joint" type="revolute">
		<origin xyz="-0.02 0.0 0.0" />
		<parent link="Body" />
		<child link="Plate" />
		<axis xyz="0 0 1" />
		<limit effort="1.8" lower="-1.57" upper="1.57" velocity="10.6" />
  </joint>
</robot>

